<?xml version="1.0" encoding="utf-8"?>
<!-- This URDF was automatically created by SolidWorks to URDF Exporter! Originally created by Stephen Brawner (brawner@gmail.com) 
     Commit Version: 1.6.0-4-g7f85cfe  Build Version: 1.6.7995.38578
     For more information, please see http://wiki.ros.org/sw_urdf_exporter -->
<robot
  name="infantry">
  <link
    name="base_link">
    <inertial>
      <origin
        xyz="0.0773396037971406 -0.0142030637172539 0.0732720572028551"
        rpy="0 0 0" />
      <mass
        value="4.01063271963357" />
      <inertia
        ixx="0.0253774532286257"
        ixy="4.00332054477323E-05"
        ixz="0.000647917369929989"
        iyy="0.062255590946904"
        iyz="-0.000753163432003692"
        izz="0.0794823661642362" />
    </inertial>
    <visual>
      <origin
        xyz="0 0 0"
        rpy="0 0 0" />
      <geometry>
        <mesh
          filename="./meshes/base_link.STL" />
      </geometry>
      <material
        name="">
        <color
          rgba="0.866666666666667 0.909803921568627 1 1" />
      </material>
    </visual>
    <collision>
      <origin
        xyz="0 0 0"
        rpy="0 0 0" />
      <geometry>
        <mesh
          filename="./meshes/base_link.STL" />
      </geometry>
    </collision>
  </link>
  <link
    name="left_leg">
    <inertial>
      <origin
        xyz="-0.08288414341075 -0.00149912062952695 -0.0243138787714042"
        rpy="0 0 0" />
      <mass
        value="0.388175393997797" />
      <inertia
        ixx="0.000297341897410301"
        ixy="0.000106750760880644"
        ixz="-0.00054272071194873"
        iyy="0.00236326839124778"
        iyz="2.91620731822173E-05"
        izz="0.00210893664364893" />
    </inertial>
    <visual>
      <origin
        xyz="0 0 0"
        rpy="0 0 0" />
      <geometry>
        <mesh
          filename="./meshes/left_leg.STL" />
      </geometry>
      <material
        name="">
        <color
          rgba="0.866666666666667 0.909803921568627 1 1" />
      </material>
    </visual>
    <collision>
      <origin
        xyz="0 0 0"
        rpy="0 0 0" />
      <geometry>
        <mesh
          filename="./meshes/left_leg.STL" />
      </geometry>
    </collision>
  </link>
  <joint
    name="left_leg"
    type="continuous">
    <origin
      xyz="0.0774339304506741 0.166046528452957 0.112513103962355"
      rpy="0 0 0" />
    <parent
      link="base_link" />
    <child
      link="left_leg" />
    <axis
      xyz="0 -1 0" />
    <limit
      lower="0"
      upper="0"
      effort="0"
      velocity="0" />
  </joint>
  <link
    name="left_small_leg">
    <inertial>
      <origin
        xyz="0.0725245855736034 0.00619237874935236 -0.0267094868548866"
        rpy="0 0 0" />
      <mass
        value="0.372624828898574" />
      <inertia
        ixx="0.000587261193183515"
        ixy="-1.09871186593458E-05"
        ixz="0.00115353457152558"
        iyy="0.00389383240250772"
        iyz="1.61246295470097E-05"
        izz="0.00334828910958965" />
    </inertial>
    <visual>
      <origin
        xyz="0 0 0"
        rpy="0 0 0" />
      <geometry>
        <mesh
          filename="./meshes/left_small_leg.STL" />
      </geometry>
      <material
        name="">
        <color
          rgba="1 1 1 1" />
      </material>
    </visual>
    <collision>
      <origin
        xyz="0 0 0"
        rpy="0 0 0" />
      <geometry>
        <mesh
          filename="./meshes/left_small_leg.STL" />
      </geometry>
    </collision>
  </link>
  <joint
    name="left_small_leg"
    type="continuous">
    <origin
      xyz="-0.205577835151374 0.0095000000000004 -0.0629504066267599"
      rpy="0 0 0" />
    <parent
      link="left_leg" />
    <child
      link="left_small_leg" />
    <axis
      xyz="0 1 0" />
    <limit
      lower="0"
      upper="0"
      effort="0"
      velocity="0" />
  </joint>
  <link
    name="left_wheel">
    <inertial>
      <origin
        xyz="0.000115991570766388 -0.00625993174818712 -0.000160100211085354"
        rpy="0 0 0" />
      <mass
        value="0.576889812400606" />
      <inertia
        ixx="0.00055800865160433"
        ixy="7.91279747646486E-07"
        ixz="-9.98740730938336E-07"
        iyy="0.000966908089769022"
        iyz="-1.07162561999686E-06"
        izz="0.000558593604726454" />
    </inertial>
    <visual>
      <origin
        xyz="0 0 0"
        rpy="0 0 0" />
      <geometry>
        <mesh
          filename="./meshes/left_wheel.STL" />
      </geometry>
      <material
        name="">
        <color
          rgba="0.866666666666667 0.909803921568627 1 1" />
      </material>
    </visual>
    <collision>
      <origin
        xyz="0 0 0"
        rpy="0 0 0" />
      <geometry>
        <mesh
          filename="./meshes/left_wheel.STL" />
      </geometry>
    </collision>
  </link>
  <joint
    name="left_wheel"
    type="continuous">
    <origin
      xyz="0.240043707112258 0.0310500000000015 -0.083036249167477"
      rpy="0 0 0" />
    <parent
      link="left_small_leg" />
    <child
      link="left_wheel" />
    <axis
      xyz="0 1 0" />
  </joint>
  <link
    name="right_leg">
    <inertial>
      <origin
        xyz="-0.0817472425401045 0.000200231692095681 -0.0239057858668973"
        rpy="0 0 0" />
      <mass
        value="0.378066882639783" />
      <inertia
        ixx="0.000290769273886285"
        ixy="-0.000101988665796749"
        ixz="-0.000530663284982633"
        iyy="0.00232136008727879"
        iyz="-2.74451144495444E-05"
        izz="0.0020714965621928" />
    </inertial>
    <visual>
      <origin
        xyz="0 0 0"
        rpy="0 0 0" />
      <geometry>
        <mesh
          filename="./meshes/right_leg.STL" />
      </geometry>
      <material
        name="">
        <color
          rgba="0.866666666666667 0.909803921568627 1 1" />
      </material>
    </visual>
    <collision>
      <origin
        xyz="0 0 0"
        rpy="0 0 0" />
      <geometry>
        <mesh
          filename="./meshes/right_leg.STL" />
      </geometry>
    </collision>
  </link>
  <joint
    name="right_leg"
    type="continuous">
    <origin
      xyz="0.0774339304506787 -0.186353471547043 0.112513103962355"
      rpy="0 0 0" />
    <parent
      link="base_link" />
    <child
      link="right_leg" />
    <axis
      xyz="0 1 0" />
    <limit
      lower="0"
      upper="0"
      effort="0"
      velocity="0" />
  </joint>
  <link
    name="right_small_leg">
    <inertial>
      <origin
        xyz="0.0723504778983492 -0.00618088751947335 -0.0260982932587692"
        rpy="0 0 0" />
      <mass
        value="0.371276470595448" />
      <inertia
        ixx="0.000563832189147727"
        ixy="1.0401396995472E-05"
        ixz="0.00112054953573551"
        iyy="0.00389292891807555"
        iyz="-1.56889725266575E-05"
        izz="0.00337078271601135" />
    </inertial>
    <visual>
      <origin
        xyz="0 0 0"
        rpy="0 0 0" />
      <geometry>
        <mesh
          filename="./meshes/right_small_leg.STL" />
      </geometry>
      <material
        name="">
        <color
          rgba="1 1 1 1" />
      </material>
    </visual>
    <collision>
      <origin
        xyz="0 0 0"
        rpy="0 0 0" />
      <geometry>
        <mesh
          filename="./meshes/right_small_leg.STL" />
      </geometry>
    </collision>
  </link>
  <joint
    name="right_small_leg"
    type="continuous">
    <origin
      xyz="-0.20557783515135 -0.0109999999999999 -0.0629504066268527"
      rpy="0 0 0" />
    <parent
      link="right_leg" />
    <child
      link="right_small_leg" />
    <axis
      xyz="0 -1 0" />
    <limit
      lower="0"
      upper="0"
      effort="0"
      velocity="0" />
  </joint>
  <link
    name="right_wheel">
    <inertial>
      <origin
        xyz="0.000159941562660131 0.0187599317481871 0.000116210234541475"
        rpy="0 0 0" />
      <mass
        value="0.576889812400577" />
      <inertia
        ixx="0.000558654137114336"
        ixy="-1.08472256780204E-06"
        ixz="9.78984302639513E-07"
        iyy="0.000966908089768991"
        iyz="-7.73228335848668E-07"
        izz="0.000557948119216415" />
    </inertial>
    <visual>
      <origin
        xyz="0 0 0"
        rpy="0 0 0" />
      <geometry>
        <mesh
          filename="./meshes/right_wheel.STL" />
      </geometry>
      <material
        name="">
        <color
          rgba="0.866666666666667 0.909803921568627 1 1" />
      </material>
    </visual>
    <collision>
      <origin
        xyz="0 0 0"
        rpy="0 0 0" />
      <geometry>
        <mesh
          filename="./meshes/right_wheel.STL" />
      </geometry>
    </collision>
  </link>
  <joint
    name="right_wheel"
    type="continuous">
    <origin
      xyz="0.24004370711208 -0.0435500000000003 -0.0830362491679966"
      rpy="0 0 0" />
    <parent
      link="right_small_leg" />
    <child
      link="right_wheel" />
    <axis
      xyz="0 -1 0" />
    <limit
      lower="0"
      upper="0"
      effort="0"
      velocity="0" />
  </joint>
</robot>